WARNING:django.request:Not Found: /favicon.ico
DEBUG:root:user loged
WARNING:django.request:Not Found: /cart/cart_status/games/games/
WARNING:django.request:Not Found: /cart/cart_status/games/games/
WARNING:django.request:Not Found: /cart/cart_status/games/games/
DEBUG:root:user loged
ERROR:django.request:Internal Server Error: /cart/sale/
Traceback (most recent call last):
  File "/usr/local/lib/python3.6/site-packages/django/core/handlers/exception.py", line 41, in inner
    response = get_response(request)
  File "/usr/local/lib/python3.6/site-packages/django/core/handlers/base.py", line 187, in _get_response
    response = self.process_exception_by_middleware(e, request)
  File "/usr/local/lib/python3.6/site-packages/django/core/handlers/base.py", line 185, in _get_response
    response = wrapped_callback(request, *callback_args, **callback_kwargs)
  File "/Users/emirozbir/Desktop/test2/gamer_trnet/epin/epinmain/views.py", line 174, in sale_finish
    add_sale_to_the_sale_table(main_template,user_id)
  File "/Users/emirozbir/Desktop/test2/gamer_trnet/epin/epinmain/views.py", line 154, in add_sale_to_the_sale_table
    conn.commit()
psycopg2.IntegrityError: insert or update on table "epinmain_sale" violates foreign key constraint "epinmain_sale_user_id_e4e7df32_fk_epinmain_profile_id"
DETAIL:  Key (user_id)=(8) is not present in table "epinmain_profile".

ERROR:django.request:Internal Server Error: /cart/sale/
Traceback (most recent call last):
  File "/usr/local/lib/python3.6/site-packages/django/core/handlers/exception.py", line 41, in inner
    response = get_response(request)
  File "/usr/local/lib/python3.6/site-packages/django/core/handlers/base.py", line 187, in _get_response
    response = self.process_exception_by_middleware(e, request)
  File "/usr/local/lib/python3.6/site-packages/django/core/handlers/base.py", line 185, in _get_response
    response = wrapped_callback(request, *callback_args, **callback_kwargs)
  File "/Users/emirozbir/Desktop/test2/gamer_trnet/epin/epinmain/views.py", line 174, in sale_finish
    add_sale_to_the_sale_table(main_template,user_id)
  File "/Users/emirozbir/Desktop/test2/gamer_trnet/epin/epinmain/views.py", line 154, in add_sale_to_the_sale_table
    conn.commit()
psycopg2.IntegrityError: insert or update on table "epinmain_sale" violates foreign key constraint "epinmain_sale_user_id_e4e7df32_fk_epinmain_profile_id"
DETAIL:  Key (user_id)=(8) is not present in table "epinmain_profile".

ERROR:django.request:Internal Server Error: /cart/sale/
Traceback (most recent call last):
  File "/usr/local/lib/python3.6/site-packages/django/core/handlers/exception.py", line 41, in inner
    response = get_response(request)
  File "/usr/local/lib/python3.6/site-packages/django/core/handlers/base.py", line 187, in _get_response
    response = self.process_exception_by_middleware(e, request)
  File "/usr/local/lib/python3.6/site-packages/django/core/handlers/base.py", line 185, in _get_response
    response = wrapped_callback(request, *callback_args, **callback_kwargs)
  File "/Users/emirozbir/Desktop/test2/gamer_trnet/epin/epinmain/views.py", line 174, in sale_finish
    add_sale_to_the_sale_table(main_template,user_id)
  File "/Users/emirozbir/Desktop/test2/gamer_trnet/epin/epinmain/views.py", line 154, in add_sale_to_the_sale_table
    conn.commit()
psycopg2.IntegrityError: insert or update on table "epinmain_sale" violates foreign key constraint "epinmain_sale_user_id_e4e7df32_fk_epinmain_profile_id"
DETAIL:  Key (user_id)=(8) is not present in table "epinmain_profile".

ERROR:django.request:Internal Server Error: /cart/sale/
Traceback (most recent call last):
  File "/usr/local/lib/python3.6/site-packages/django/core/handlers/exception.py", line 41, in inner
    response = get_response(request)
  File "/usr/local/lib/python3.6/site-packages/django/core/handlers/base.py", line 187, in _get_response
    response = self.process_exception_by_middleware(e, request)
  File "/usr/local/lib/python3.6/site-packages/django/core/handlers/base.py", line 185, in _get_response
    response = wrapped_callback(request, *callback_args, **callback_kwargs)
  File "/Users/emirozbir/Desktop/test2/gamer_trnet/epin/epinmain/views.py", line 174, in sale_finish
    add_sale_to_the_sale_table(main_template,user_id)
  File "/Users/emirozbir/Desktop/test2/gamer_trnet/epin/epinmain/views.py", line 154, in add_sale_to_the_sale_table
    conn.commit()
psycopg2.IntegrityError: insert or update on table "epinmain_sale" violates foreign key constraint "epinmain_sale_user_id_e4e7df32_fk_epinmain_profile_id"
DETAIL:  Key (user_id)=(8) is not present in table "epinmain_profile".

WARNING:django.request:Not Found: /favicon.ico
WARNING:django.request:Not Found: /accounts/logout
WARNING:django.request:Not Found: /accounts/invalid/
WARNING:django.request:Not Found: /accounts/login
WARNING:django.request:Not Found: /accounts/login
DEBUG:django.db.backends:(0.003) 
            SELECT c.relname, c.relkind
            FROM pg_catalog.pg_class c
            LEFT JOIN pg_catalog.pg_namespace n ON n.oid = c.relnamespace
            WHERE c.relkind IN ('r', 'v')
                AND n.nspname NOT IN ('pg_catalog', 'pg_toast')
                AND pg_catalog.pg_table_is_visible(c.oid); args=None
DEBUG:django.db.backends:(0.000) SELECT "django_migrations"."app", "django_migrations"."name" FROM "django_migrations"; args=()
DEBUG:django.db.backends:(0.004) 
            SELECT c.relname, c.relkind
            FROM pg_catalog.pg_class c
            LEFT JOIN pg_catalog.pg_namespace n ON n.oid = c.relnamespace
            WHERE c.relkind IN ('r', 'v')
                AND n.nspname NOT IN ('pg_catalog', 'pg_toast')
                AND pg_catalog.pg_table_is_visible(c.oid); args=None
DEBUG:django.db.backends:(0.001) SELECT "django_migrations"."app", "django_migrations"."name" FROM "django_migrations"; args=()
DEBUG:django.template:Exception while resolving variable 'form' in template 'login.html'.
Traceback (most recent call last):
  File "/usr/local/lib/python3.6/site-packages/django/template/base.py", line 882, in _resolve_lookup
    current = current[bit]
  File "/usr/local/lib/python3.6/site-packages/django/template/context.py", line 87, in __getitem__
    raise KeyError(key)
KeyError: 'form'

During handling of the above exception, another exception occurred:

Traceback (most recent call last):
  File "/usr/local/lib/python3.6/site-packages/django/template/base.py", line 888, in _resolve_lookup
    if isinstance(current, BaseContext) and getattr(type(current), bit):
AttributeError: type object 'Context' has no attribute 'form'

During handling of the above exception, another exception occurred:

Traceback (most recent call last):
  File "/usr/local/lib/python3.6/site-packages/django/template/base.py", line 896, in _resolve_lookup
    current = current[int(bit)]
ValueError: invalid literal for int() with base 10: 'form'

During handling of the above exception, another exception occurred:

Traceback (most recent call last):
  File "/usr/local/lib/python3.6/site-packages/django/template/base.py", line 903, in _resolve_lookup
    (bit, current))  # missing attribute
django.template.base.VariableDoesNotExist: Failed lookup for key [form] in "[{'True': True, 'False': False, 'None': None}, {'csrf_token': <SimpleLazyObject: <function csrf.<locals>._get_val at 0x1058c4950>>}]"
INFO:django.server:"GET /accounts/login/ HTTP/1.1" 200 419
DEBUG:django.db.backends:(0.004) 
            SELECT c.relname, c.relkind
            FROM pg_catalog.pg_class c
            LEFT JOIN pg_catalog.pg_namespace n ON n.oid = c.relnamespace
            WHERE c.relkind IN ('r', 'v')
                AND n.nspname NOT IN ('pg_catalog', 'pg_toast')
                AND pg_catalog.pg_table_is_visible(c.oid); args=None
DEBUG:django.db.backends:(0.001) SELECT "django_migrations"."app", "django_migrations"."name" FROM "django_migrations"; args=()
ERROR:django.request:Internal Server Error: /accounts/login/
Traceback (most recent call last):
  File "/usr/local/lib/python3.6/site-packages/django/core/handlers/exception.py", line 41, in inner
    response = get_response(request)
  File "/usr/local/lib/python3.6/site-packages/django/core/handlers/base.py", line 187, in _get_response
    response = self.process_exception_by_middleware(e, request)
  File "/usr/local/lib/python3.6/site-packages/django/core/handlers/base.py", line 185, in _get_response
    response = wrapped_callback(request, *callback_args, **callback_kwargs)
  File "/Users/emirozbir/Desktop/gamer_trnet/epin/epinmain/views.py", line 96, in login
    return render('games.html', c)
  File "/usr/local/lib/python3.6/site-packages/django/shortcuts.py", line 30, in render
    content = loader.render_to_string(template_name, context, request, using=using)
  File "/usr/local/lib/python3.6/site-packages/django/template/loader.py", line 67, in render_to_string
    template = get_template(template_name, using=using)
  File "/usr/local/lib/python3.6/site-packages/django/template/loader.py", line 25, in get_template
    raise TemplateDoesNotExist(template_name, chain=chain)
django.template.exceptions.TemplateDoesNotExist: {'csrf_token': <SimpleLazyObject: <function csrf.<locals>._get_val at 0x1087709d8>>}
ERROR:django.request:Internal Server Error: /games/games/
Traceback (most recent call last):
  File "/usr/local/lib/python3.6/site-packages/django/core/handlers/exception.py", line 41, in inner
    response = get_response(request)
  File "/usr/local/lib/python3.6/site-packages/django/core/handlers/base.py", line 187, in _get_response
    response = self.process_exception_by_middleware(e, request)
  File "/usr/local/lib/python3.6/site-packages/django/core/handlers/base.py", line 185, in _get_response
    response = wrapped_callback(request, *callback_args, **callback_kwargs)
  File "/Users/emirozbir/Desktop/gamer_trnet/epin/epinmain/views.py", line 80, in games
    my_keys = request.session['game']
  File "/usr/local/lib/python3.6/site-packages/django/contrib/sessions/backends/base.py", line 57, in __getitem__
    return self._session[key]
KeyError: 'game'
ERROR:django.request:Internal Server Error: /games/games/
Traceback (most recent call last):
  File "/usr/local/lib/python3.6/site-packages/django/core/handlers/exception.py", line 41, in inner
    response = get_response(request)
  File "/usr/local/lib/python3.6/site-packages/django/core/handlers/base.py", line 187, in _get_response
    response = self.process_exception_by_middleware(e, request)
  File "/usr/local/lib/python3.6/site-packages/django/core/handlers/base.py", line 185, in _get_response
    response = wrapped_callback(request, *callback_args, **callback_kwargs)
  File "/Users/emirozbir/Desktop/gamer_trnet/epin/epinmain/views.py", line 80, in games
    my_keys = request.session['game']
  File "/usr/local/lib/python3.6/site-packages/django/contrib/sessions/backends/base.py", line 57, in __getitem__
    return self._session[key]
KeyError: 'game'
ERROR:django.request:Internal Server Error: /games/games/
Traceback (most recent call last):
  File "/usr/local/lib/python3.6/site-packages/django/core/handlers/exception.py", line 41, in inner
    response = get_response(request)
  File "/usr/local/lib/python3.6/site-packages/django/core/handlers/base.py", line 187, in _get_response
    response = self.process_exception_by_middleware(e, request)
  File "/usr/local/lib/python3.6/site-packages/django/core/handlers/base.py", line 185, in _get_response
    response = wrapped_callback(request, *callback_args, **callback_kwargs)
  File "/Users/emirozbir/Desktop/gamer_trnet/epin/epinmain/views.py", line 80, in games
    my_keys = request.session['game']
  File "/usr/local/lib/python3.6/site-packages/django/contrib/sessions/backends/base.py", line 57, in __getitem__
    return self._session[key]
KeyError: 'game'
DEBUG:root:user loged
ERROR:epinmain.views:Something went wrong!
INFO:epinmain.views:hello
WARNING:django.request:Not Found: /cart/cart_status/games/games/
