DEBUG:root:USER admin FETCHED GAMES
DEBUG:root:USER admin FETCHED GAMES
DEBUG:root:USER admin FETCHED GAMES
DEBUG:root:USER AnonymousUser LOGOUT 
DEBUG:root:USER AnonymousUser CREATED  
DEBUG:root:USER emirozbir FETCHED GAMES
DEBUG:root:USER emirozbir FETCHED GAMES
DEBUG:root:USER emirozbir FETCHED GAMES
DEBUG:root:USER emirozbir FETCHED GAMES
DEBUG:root:USER emirozbir FETCHED GAMES
DEBUG:root:USER emirozbir FETCHED GAMES
WARNING:django.request:Not Found: /account/login/
DEBUG:root:USER AnonymousUser LOGOUT 
DEBUG:root:USER AnonymousUser LOGOUT 
DEBUG:root:USER emirozbir FETCHED GAMES
ERROR:django.request:Internal Server Error: /games/games/
Traceback (most recent call last):
  File "/usr/local/lib/python3.6/site-packages/django/db/backends/utils.py", line 63, in execute
    return self.cursor.execute(sql)
psycopg2.ProgrammingError: relation "game" does not exist
LINE 1: SELECT * FROM game
                      ^


The above exception was the direct cause of the following exception:

Traceback (most recent call last):
  File "/usr/local/lib/python3.6/site-packages/django/core/handlers/exception.py", line 41, in inner
    response = get_response(request)
  File "/usr/local/lib/python3.6/site-packages/django/core/handlers/base.py", line 187, in _get_response
    response = self.process_exception_by_middleware(e, request)
  File "/usr/local/lib/python3.6/site-packages/django/core/handlers/base.py", line 185, in _get_response
    response = wrapped_callback(request, *callback_args, **callback_kwargs)
  File "/Users/emirozbir/Desktop/desktop/gamer_trnet-yedek/epin/epinmain/views.py", line 47, in games
    return render_to_response("tr/oyunlar.html",{"game_data":fetch_all_game()})
  File "/Users/emirozbir/Desktop/desktop/gamer_trnet-yedek/epin/epinmain/views.py", line 35, in fetch_all_game
    games = cursor.execute("SELECT * FROM game")
  File "/usr/local/lib/python3.6/site-packages/django/db/backends/utils.py", line 80, in execute
    return super(CursorDebugWrapper, self).execute(sql, params)
  File "/usr/local/lib/python3.6/site-packages/django/db/backends/utils.py", line 65, in execute
    return self.cursor.execute(sql, params)
  File "/usr/local/lib/python3.6/site-packages/django/db/utils.py", line 94, in __exit__
    six.reraise(dj_exc_type, dj_exc_value, traceback)
  File "/usr/local/lib/python3.6/site-packages/django/utils/six.py", line 685, in reraise
    raise value.with_traceback(tb)
  File "/usr/local/lib/python3.6/site-packages/django/db/backends/utils.py", line 63, in execute
    return self.cursor.execute(sql)
django.db.utils.ProgrammingError: relation "game" does not exist
LINE 1: SELECT * FROM game
                      ^

ERROR:django.request:Internal Server Error: /accounts/login/
Traceback (most recent call last):
  File "/usr/local/lib/python3.6/site-packages/django/core/handlers/exception.py", line 41, in inner
    response = get_response(request)
  File "/usr/local/lib/python3.6/site-packages/django/core/handlers/base.py", line 187, in _get_response
    response = self.process_exception_by_middleware(e, request)
  File "/usr/local/lib/python3.6/site-packages/django/core/handlers/base.py", line 185, in _get_response
    response = wrapped_callback(request, *callback_args, **callback_kwargs)
  File "/Users/emirozbir/Desktop/desktop/gamer_trnet-yedek/epin/epinmain/views.py", line 62, in index
    return render(request,"eng/index.html")
  File "/usr/local/lib/python3.6/site-packages/django/shortcuts.py", line 30, in render
    content = loader.render_to_string(template_name, context, request, using=using)
  File "/usr/local/lib/python3.6/site-packages/django/template/loader.py", line 67, in render_to_string
    template = get_template(template_name, using=using)
  File "/usr/local/lib/python3.6/site-packages/django/template/loader.py", line 25, in get_template
    raise TemplateDoesNotExist(template_name, chain=chain)
django.template.exceptions.TemplateDoesNotExist: eng/index.html
WARNING:django.request:Not Found: /account/login/
ERROR:django.request:Internal Server Error: /accounts/login/
Traceback (most recent call last):
  File "/usr/local/lib/python3.6/site-packages/django/core/handlers/exception.py", line 41, in inner
    response = get_response(request)
  File "/usr/local/lib/python3.6/site-packages/django/core/handlers/base.py", line 187, in _get_response
    response = self.process_exception_by_middleware(e, request)
  File "/usr/local/lib/python3.6/site-packages/django/core/handlers/base.py", line 185, in _get_response
    response = wrapped_callback(request, *callback_args, **callback_kwargs)
  File "/Users/emirozbir/Desktop/desktop/gamer_trnet-yedek/epin/epinmain/views.py", line 62, in index
    return render(request,"eng/index.html")
  File "/usr/local/lib/python3.6/site-packages/django/shortcuts.py", line 30, in render
    content = loader.render_to_string(template_name, context, request, using=using)
  File "/usr/local/lib/python3.6/site-packages/django/template/loader.py", line 67, in render_to_string
    template = get_template(template_name, using=using)
  File "/usr/local/lib/python3.6/site-packages/django/template/loader.py", line 25, in get_template
    raise TemplateDoesNotExist(template_name, chain=chain)
django.template.exceptions.TemplateDoesNotExist: eng/index.html
WARNING:django.request:Not Found: /account/login/
ERROR:django.request:Internal Server Error: /accounts/login/
Traceback (most recent call last):
  File "/usr/local/lib/python3.6/site-packages/django/core/handlers/exception.py", line 41, in inner
    response = get_response(request)
  File "/usr/local/lib/python3.6/site-packages/django/core/handlers/base.py", line 187, in _get_response
    response = self.process_exception_by_middleware(e, request)
  File "/usr/local/lib/python3.6/site-packages/django/core/handlers/base.py", line 185, in _get_response
    response = wrapped_callback(request, *callback_args, **callback_kwargs)
  File "/Users/emirozbir/Desktop/desktop/gamer_trnet-yedek/epin/epinmain/views.py", line 62, in index
    return render(request,"tr/index.html")
  File "/usr/local/lib/python3.6/site-packages/django/shortcuts.py", line 30, in render
    content = loader.render_to_string(template_name, context, request, using=using)
  File "/usr/local/lib/python3.6/site-packages/django/template/loader.py", line 67, in render_to_string
    template = get_template(template_name, using=using)
  File "/usr/local/lib/python3.6/site-packages/django/template/loader.py", line 25, in get_template
    raise TemplateDoesNotExist(template_name, chain=chain)
django.template.exceptions.TemplateDoesNotExist: tr/index.html
WARNING:django.request:Not Found: /favicon.ico
DEBUG:root:USER AnonymousUser LOGOUT 
WARNING:django.request:Not Found: /favicon.ico
DEBUG:root:USER emirozbir FETCHED GAMES
ERROR:django.request:Internal Server Error: /games/games/
Traceback (most recent call last):
  File "/usr/local/lib/python3.6/site-packages/django/db/backends/utils.py", line 63, in execute
    return self.cursor.execute(sql)
psycopg2.ProgrammingError: relation "game" does not exist
LINE 1: SELECT * FROM game
                      ^


The above exception was the direct cause of the following exception:

Traceback (most recent call last):
  File "/usr/local/lib/python3.6/site-packages/django/core/handlers/exception.py", line 41, in inner
    response = get_response(request)
  File "/usr/local/lib/python3.6/site-packages/django/core/handlers/base.py", line 187, in _get_response
    response = self.process_exception_by_middleware(e, request)
  File "/usr/local/lib/python3.6/site-packages/django/core/handlers/base.py", line 185, in _get_response
    response = wrapped_callback(request, *callback_args, **callback_kwargs)
  File "/Users/emirozbir/Desktop/desktop/gamer_trnet-yedek/epin/epinmain/views.py", line 47, in games
    return render_to_response("tr/oyunlar.html",{"game_data":fetch_all_game()})
  File "/Users/emirozbir/Desktop/desktop/gamer_trnet-yedek/epin/epinmain/views.py", line 35, in fetch_all_game
    games = cursor.execute("SELECT * FROM game")
  File "/usr/local/lib/python3.6/site-packages/django/db/backends/utils.py", line 80, in execute
    return super(CursorDebugWrapper, self).execute(sql, params)
  File "/usr/local/lib/python3.6/site-packages/django/db/backends/utils.py", line 65, in execute
    return self.cursor.execute(sql, params)
  File "/usr/local/lib/python3.6/site-packages/django/db/utils.py", line 94, in __exit__
    six.reraise(dj_exc_type, dj_exc_value, traceback)
  File "/usr/local/lib/python3.6/site-packages/django/utils/six.py", line 685, in reraise
    raise value.with_traceback(tb)
  File "/usr/local/lib/python3.6/site-packages/django/db/backends/utils.py", line 63, in execute
    return self.cursor.execute(sql)
django.db.utils.ProgrammingError: relation "game" does not exist
LINE 1: SELECT * FROM game
                      ^

DEBUG:root:USER emirozbir FETCHED GAMES
ERROR:django.request:Internal Server Error: /games/games/
Traceback (most recent call last):
  File "/usr/local/lib/python3.6/site-packages/django/db/backends/utils.py", line 63, in execute
    return self.cursor.execute(sql)
psycopg2.ProgrammingError: relation "game" does not exist
LINE 1: SELECT * FROM game
                      ^


The above exception was the direct cause of the following exception:

Traceback (most recent call last):
  File "/usr/local/lib/python3.6/site-packages/django/core/handlers/exception.py", line 41, in inner
    response = get_response(request)
  File "/usr/local/lib/python3.6/site-packages/django/core/handlers/base.py", line 187, in _get_response
    response = self.process_exception_by_middleware(e, request)
  File "/usr/local/lib/python3.6/site-packages/django/core/handlers/base.py", line 185, in _get_response
    response = wrapped_callback(request, *callback_args, **callback_kwargs)
  File "/Users/emirozbir/Desktop/desktop/gamer_trnet-yedek/epin/epinmain/views.py", line 47, in games
    return render_to_response("tr/oyunlar.html",{"game_data":fetch_all_game()})
  File "/Users/emirozbir/Desktop/desktop/gamer_trnet-yedek/epin/epinmain/views.py", line 35, in fetch_all_game
    games = cursor.execute("SELECT * FROM game")
  File "/usr/local/lib/python3.6/site-packages/django/db/backends/utils.py", line 80, in execute
    return super(CursorDebugWrapper, self).execute(sql, params)
  File "/usr/local/lib/python3.6/site-packages/django/db/backends/utils.py", line 65, in execute
    return self.cursor.execute(sql, params)
  File "/usr/local/lib/python3.6/site-packages/django/db/utils.py", line 94, in __exit__
    six.reraise(dj_exc_type, dj_exc_value, traceback)
  File "/usr/local/lib/python3.6/site-packages/django/utils/six.py", line 685, in reraise
    raise value.with_traceback(tb)
  File "/usr/local/lib/python3.6/site-packages/django/db/backends/utils.py", line 63, in execute
    return self.cursor.execute(sql)
django.db.utils.ProgrammingError: relation "game" does not exist
LINE 1: SELECT * FROM game
                      ^

DEBUG:root:USER AnonymousUser LOGOUT 
DEBUG:root:USER emirozbir FETCHED GAMES
ERROR:django.request:Internal Server Error: /games/games/
Traceback (most recent call last):
  File "/usr/local/lib/python3.6/site-packages/django/db/backends/utils.py", line 63, in execute
    return self.cursor.execute(sql)
psycopg2.ProgrammingError: relation "game" does not exist
LINE 1: SELECT * FROM game
                      ^


The above exception was the direct cause of the following exception:

Traceback (most recent call last):
  File "/usr/local/lib/python3.6/site-packages/django/core/handlers/exception.py", line 41, in inner
    response = get_response(request)
  File "/usr/local/lib/python3.6/site-packages/django/core/handlers/base.py", line 187, in _get_response
    response = self.process_exception_by_middleware(e, request)
  File "/usr/local/lib/python3.6/site-packages/django/core/handlers/base.py", line 185, in _get_response
    response = wrapped_callback(request, *callback_args, **callback_kwargs)
  File "/Users/emirozbir/Desktop/desktop/gamer_trnet-yedek/epin/epinmain/views.py", line 47, in games
    return render_to_response("tr/oyunlar.html",{"game_data":fetch_all_game()})
  File "/Users/emirozbir/Desktop/desktop/gamer_trnet-yedek/epin/epinmain/views.py", line 35, in fetch_all_game
    games = cursor.execute("SELECT * FROM game")
  File "/usr/local/lib/python3.6/site-packages/django/db/backends/utils.py", line 80, in execute
    return super(CursorDebugWrapper, self).execute(sql, params)
  File "/usr/local/lib/python3.6/site-packages/django/db/backends/utils.py", line 65, in execute
    return self.cursor.execute(sql, params)
  File "/usr/local/lib/python3.6/site-packages/django/db/utils.py", line 94, in __exit__
    six.reraise(dj_exc_type, dj_exc_value, traceback)
  File "/usr/local/lib/python3.6/site-packages/django/utils/six.py", line 685, in reraise
    raise value.with_traceback(tb)
  File "/usr/local/lib/python3.6/site-packages/django/db/backends/utils.py", line 63, in execute
    return self.cursor.execute(sql)
django.db.utils.ProgrammingError: relation "game" does not exist
LINE 1: SELECT * FROM game
                      ^

DEBUG:root:USER emirozbir FETCHED GAMES
ERROR:django.request:Internal Server Error: /games/games/
Traceback (most recent call last):
  File "/usr/local/lib/python3.6/site-packages/django/db/backends/utils.py", line 63, in execute
    return self.cursor.execute(sql)
psycopg2.ProgrammingError: relation "game" does not exist
LINE 1: SELECT * FROM game
                      ^


The above exception was the direct cause of the following exception:

Traceback (most recent call last):
  File "/usr/local/lib/python3.6/site-packages/django/core/handlers/exception.py", line 41, in inner
    response = get_response(request)
  File "/usr/local/lib/python3.6/site-packages/django/core/handlers/base.py", line 187, in _get_response
    response = self.process_exception_by_middleware(e, request)
  File "/usr/local/lib/python3.6/site-packages/django/core/handlers/base.py", line 185, in _get_response
    response = wrapped_callback(request, *callback_args, **callback_kwargs)
  File "/Users/emirozbir/Desktop/desktop/gamer_trnet-yedek/epin/epinmain/views.py", line 47, in games
    return render_to_response("tr/oyunlar.html",{"game_data":fetch_all_game()})
  File "/Users/emirozbir/Desktop/desktop/gamer_trnet-yedek/epin/epinmain/views.py", line 35, in fetch_all_game
    games = cursor.execute("SELECT * FROM game")
  File "/usr/local/lib/python3.6/site-packages/django/db/backends/utils.py", line 80, in execute
    return super(CursorDebugWrapper, self).execute(sql, params)
  File "/usr/local/lib/python3.6/site-packages/django/db/backends/utils.py", line 65, in execute
    return self.cursor.execute(sql, params)
  File "/usr/local/lib/python3.6/site-packages/django/db/utils.py", line 94, in __exit__
    six.reraise(dj_exc_type, dj_exc_value, traceback)
  File "/usr/local/lib/python3.6/site-packages/django/utils/six.py", line 685, in reraise
    raise value.with_traceback(tb)
  File "/usr/local/lib/python3.6/site-packages/django/db/backends/utils.py", line 63, in execute
    return self.cursor.execute(sql)
django.db.utils.ProgrammingError: relation "game" does not exist
LINE 1: SELECT * FROM game
                      ^

DEBUG:root:USER emirozbir FETCHED GAMES
ERROR:django.request:Internal Server Error: /games/games/
Traceback (most recent call last):
  File "/usr/local/lib/python3.6/site-packages/django/db/backends/utils.py", line 63, in execute
    return self.cursor.execute(sql)
psycopg2.ProgrammingError: relation "game" does not exist
LINE 1: SELECT * FROM game
                      ^


The above exception was the direct cause of the following exception:

Traceback (most recent call last):
  File "/usr/local/lib/python3.6/site-packages/django/core/handlers/exception.py", line 41, in inner
    response = get_response(request)
  File "/usr/local/lib/python3.6/site-packages/django/core/handlers/base.py", line 187, in _get_response
    response = self.process_exception_by_middleware(e, request)
  File "/usr/local/lib/python3.6/site-packages/django/core/handlers/base.py", line 185, in _get_response
    response = wrapped_callback(request, *callback_args, **callback_kwargs)
  File "/Users/emirozbir/Desktop/desktop/gamer_trnet-yedek/epin/epinmain/views.py", line 47, in games
    return render_to_response("tr/oyunlar.html",{"game_data":fetch_all_game()})
  File "/Users/emirozbir/Desktop/desktop/gamer_trnet-yedek/epin/epinmain/views.py", line 35, in fetch_all_game
    games = cursor.execute("SELECT * FROM game")
  File "/usr/local/lib/python3.6/site-packages/django/db/backends/utils.py", line 80, in execute
    return super(CursorDebugWrapper, self).execute(sql, params)
  File "/usr/local/lib/python3.6/site-packages/django/db/backends/utils.py", line 65, in execute
    return self.cursor.execute(sql, params)
  File "/usr/local/lib/python3.6/site-packages/django/db/utils.py", line 94, in __exit__
    six.reraise(dj_exc_type, dj_exc_value, traceback)
  File "/usr/local/lib/python3.6/site-packages/django/utils/six.py", line 685, in reraise
    raise value.with_traceback(tb)
  File "/usr/local/lib/python3.6/site-packages/django/db/backends/utils.py", line 63, in execute
    return self.cursor.execute(sql)
django.db.utils.ProgrammingError: relation "game" does not exist
LINE 1: SELECT * FROM game
                      ^

DEBUG:root:USER emirozbir FETCHED GAMES
ERROR:django.request:Internal Server Error: /games/games/
Traceback (most recent call last):
  File "/usr/local/lib/python3.6/site-packages/django/db/backends/utils.py", line 63, in execute
    return self.cursor.execute(sql)
psycopg2.ProgrammingError: relation "game" does not exist
LINE 1: SELECT * FROM game
                      ^


The above exception was the direct cause of the following exception:

Traceback (most recent call last):
  File "/usr/local/lib/python3.6/site-packages/django/core/handlers/exception.py", line 41, in inner
    response = get_response(request)
  File "/usr/local/lib/python3.6/site-packages/django/core/handlers/base.py", line 187, in _get_response
    response = self.process_exception_by_middleware(e, request)
  File "/usr/local/lib/python3.6/site-packages/django/core/handlers/base.py", line 185, in _get_response
    response = wrapped_callback(request, *callback_args, **callback_kwargs)
  File "/Users/emirozbir/Desktop/desktop/gamer_trnet-yedek/epin/epinmain/views.py", line 47, in games
    return render_to_response("tr/oyunlar.html",{"game_data":fetch_all_game()})
  File "/Users/emirozbir/Desktop/desktop/gamer_trnet-yedek/epin/epinmain/views.py", line 35, in fetch_all_game
    games = cursor.execute("SELECT * FROM game")
  File "/usr/local/lib/python3.6/site-packages/django/db/backends/utils.py", line 80, in execute
    return super(CursorDebugWrapper, self).execute(sql, params)
  File "/usr/local/lib/python3.6/site-packages/django/db/backends/utils.py", line 65, in execute
    return self.cursor.execute(sql, params)
  File "/usr/local/lib/python3.6/site-packages/django/db/utils.py", line 94, in __exit__
    six.reraise(dj_exc_type, dj_exc_value, traceback)
  File "/usr/local/lib/python3.6/site-packages/django/utils/six.py", line 685, in reraise
    raise value.with_traceback(tb)
  File "/usr/local/lib/python3.6/site-packages/django/db/backends/utils.py", line 63, in execute
    return self.cursor.execute(sql)
django.db.utils.ProgrammingError: relation "game" does not exist
LINE 1: SELECT * FROM game
                      ^

WARNING:django.request:Not Found: /games/game/
DEBUG:root:USER emirozbir FETCHED GAMES
ERROR:django.request:Internal Server Error: /games/games/
Traceback (most recent call last):
  File "/usr/local/lib/python3.6/site-packages/django/db/backends/utils.py", line 63, in execute
    return self.cursor.execute(sql)
psycopg2.ProgrammingError: relation "game" does not exist
LINE 1: SELECT * FROM game
                      ^


The above exception was the direct cause of the following exception:

Traceback (most recent call last):
  File "/usr/local/lib/python3.6/site-packages/django/core/handlers/exception.py", line 41, in inner
    response = get_response(request)
  File "/usr/local/lib/python3.6/site-packages/django/core/handlers/base.py", line 187, in _get_response
    response = self.process_exception_by_middleware(e, request)
  File "/usr/local/lib/python3.6/site-packages/django/core/handlers/base.py", line 185, in _get_response
    response = wrapped_callback(request, *callback_args, **callback_kwargs)
  File "/Users/emirozbir/Desktop/desktop/gamer_trnet-yedek/epin/epinmain/views.py", line 47, in games
    return render_to_response("tr/oyunlar.html",{"game_data":fetch_all_game()})
  File "/Users/emirozbir/Desktop/desktop/gamer_trnet-yedek/epin/epinmain/views.py", line 35, in fetch_all_game
    games = cursor.execute("SELECT * FROM game")
  File "/usr/local/lib/python3.6/site-packages/django/db/backends/utils.py", line 80, in execute
    return super(CursorDebugWrapper, self).execute(sql, params)
  File "/usr/local/lib/python3.6/site-packages/django/db/backends/utils.py", line 65, in execute
    return self.cursor.execute(sql, params)
  File "/usr/local/lib/python3.6/site-packages/django/db/utils.py", line 94, in __exit__
    six.reraise(dj_exc_type, dj_exc_value, traceback)
  File "/usr/local/lib/python3.6/site-packages/django/utils/six.py", line 685, in reraise
    raise value.with_traceback(tb)
  File "/usr/local/lib/python3.6/site-packages/django/db/backends/utils.py", line 63, in execute
    return self.cursor.execute(sql)
django.db.utils.ProgrammingError: relation "game" does not exist
LINE 1: SELECT * FROM game
                      ^

DEBUG:root:USER emirozbir FETCHED GAMES
ERROR:django.request:Internal Server Error: /games/games/
Traceback (most recent call last):
  File "/usr/local/lib/python3.6/site-packages/django/db/backends/utils.py", line 63, in execute
    return self.cursor.execute(sql)
psycopg2.ProgrammingError: relation "game" does not exist
LINE 1: SELECT * FROM game
                      ^


The above exception was the direct cause of the following exception:

Traceback (most recent call last):
  File "/usr/local/lib/python3.6/site-packages/django/core/handlers/exception.py", line 41, in inner
    response = get_response(request)
  File "/usr/local/lib/python3.6/site-packages/django/core/handlers/base.py", line 187, in _get_response
    response = self.process_exception_by_middleware(e, request)
  File "/usr/local/lib/python3.6/site-packages/django/core/handlers/base.py", line 185, in _get_response
    response = wrapped_callback(request, *callback_args, **callback_kwargs)
  File "/Users/emirozbir/Desktop/desktop/gamer_trnet-yedek/epin/epinmain/views.py", line 51, in games
    return render_to_response("eng/games.html", {"game_data": fetch_all_game()})
  File "/Users/emirozbir/Desktop/desktop/gamer_trnet-yedek/epin/epinmain/views.py", line 35, in fetch_all_game
    games = cursor.execute("SELECT * FROM game")
  File "/usr/local/lib/python3.6/site-packages/django/db/backends/utils.py", line 80, in execute
    return super(CursorDebugWrapper, self).execute(sql, params)
  File "/usr/local/lib/python3.6/site-packages/django/db/backends/utils.py", line 65, in execute
    return self.cursor.execute(sql, params)
  File "/usr/local/lib/python3.6/site-packages/django/db/utils.py", line 94, in __exit__
    six.reraise(dj_exc_type, dj_exc_value, traceback)
  File "/usr/local/lib/python3.6/site-packages/django/utils/six.py", line 685, in reraise
    raise value.with_traceback(tb)
  File "/usr/local/lib/python3.6/site-packages/django/db/backends/utils.py", line 63, in execute
    return self.cursor.execute(sql)
django.db.utils.ProgrammingError: relation "game" does not exist
LINE 1: SELECT * FROM game
                      ^

DEBUG:root:USER emirozbir FETCHED GAMES
ERROR:django.request:Internal Server Error: /games/games/
Traceback (most recent call last):
  File "/usr/local/lib/python3.6/site-packages/django/core/handlers/exception.py", line 41, in inner
    response = get_response(request)
  File "/usr/local/lib/python3.6/site-packages/django/core/handlers/base.py", line 187, in _get_response
    response = self.process_exception_by_middleware(e, request)
  File "/usr/local/lib/python3.6/site-packages/django/core/handlers/base.py", line 185, in _get_response
    response = wrapped_callback(request, *callback_args, **callback_kwargs)
  File "/Users/emirozbir/Desktop/desktop/gamer_trnet-yedek/epin/epinmain/views.py", line 51, in games
    return render_to_response("eng/games.html", {"game_data": fetch_all_game()})
  File "/usr/local/lib/python3.6/site-packages/django/shortcuts.py", line 21, in render_to_response
    content = loader.render_to_string(template_name, context, using=using)
  File "/usr/local/lib/python3.6/site-packages/django/template/loader.py", line 68, in render_to_string
    return template.render(context, request)
  File "/usr/local/lib/python3.6/site-packages/django/template/backends/django.py", line 66, in render
    return self.template.render(context)
  File "/usr/local/lib/python3.6/site-packages/django/template/base.py", line 207, in render
    return self._render(context)
  File "/usr/local/lib/python3.6/site-packages/django/template/base.py", line 199, in _render
    return self.nodelist.render(context)
  File "/usr/local/lib/python3.6/site-packages/django/template/base.py", line 990, in render
    bit = node.render_annotated(context)
  File "/usr/local/lib/python3.6/site-packages/django/template/base.py", line 957, in render_annotated
    return self.render(context)
  File "/usr/local/lib/python3.6/site-packages/django/template/defaulttags.py", line 207, in render
    .format(num_loopvars, len_item),
ValueError: Need 2 values to unpack in for loop; got 0. 
DEBUG:root:USER emirozbir FETCHED GAMES
DEBUG:root:USER emirozbir FETCHED GAMES
DEBUG:root:USER emirozbir FETCHED GAMES
DEBUG:root:USER emirozbir FETCHED GAMES
DEBUG:root:USER emirozbir FETCHED GAMES
DEBUG:root:USER emirozbir FETCHED GAMES
DEBUG:root:USER emirozbir FETCHED GAMES
DEBUG:root:USER AnonymousUser LOGOUT 
DEBUG:root:USER emirozbir FETCHED GAMES
ERROR:django.request:Internal Server Error: /games/games/
Traceback (most recent call last):
  File "/usr/local/lib/python3.6/site-packages/django/core/handlers/exception.py", line 41, in inner
    response = get_response(request)
  File "/usr/local/lib/python3.6/site-packages/django/core/handlers/base.py", line 187, in _get_response
    response = self.process_exception_by_middleware(e, request)
  File "/usr/local/lib/python3.6/site-packages/django/core/handlers/base.py", line 185, in _get_response
    response = wrapped_callback(request, *callback_args, **callback_kwargs)
  File "/Users/emirozbir/Desktop/desktop/gamer_trnet-yedek/epin/epinmain/views.py", line 48, in games
    return render_to_response("tr/oyunlar.html",{"game_data":fetch_all_game()})
  File "/usr/local/lib/python3.6/site-packages/django/shortcuts.py", line 21, in render_to_response
    content = loader.render_to_string(template_name, context, using=using)
  File "/usr/local/lib/python3.6/site-packages/django/template/loader.py", line 68, in render_to_string
    return template.render(context, request)
  File "/usr/local/lib/python3.6/site-packages/django/template/backends/django.py", line 66, in render
    return self.template.render(context)
  File "/usr/local/lib/python3.6/site-packages/django/template/base.py", line 207, in render
    return self._render(context)
  File "/usr/local/lib/python3.6/site-packages/django/template/base.py", line 199, in _render
    return self.nodelist.render(context)
  File "/usr/local/lib/python3.6/site-packages/django/template/base.py", line 990, in render
    bit = node.render_annotated(context)
  File "/usr/local/lib/python3.6/site-packages/django/template/base.py", line 957, in render_annotated
    return self.render(context)
  File "/usr/local/lib/python3.6/site-packages/django/template/defaulttags.py", line 207, in render
    .format(num_loopvars, len_item),
ValueError: Need 2 values to unpack in for loop; got 0. 
DEBUG:root:USER emirozbir FETCHED GAMES
WARNING:django.request:Not Found: /
WARNING:django.request:Not Found: /
WARNING:django.request:Not Found: /
WARNING:django.request:Not Found: /
WARNING:django.request:Not Found: /
WARNING:django.request:Not Found: /
WARNING:django.request:Not Found: /
WARNING:django.request:Not Found: /
WARNING:django.request:Not Found: /
WARNING:django.request:Not Found: /
WARNING:django.request:Not Found: /
WARNING:django.request:Not Found: /base
WARNING:django.request:Not Found: /base.html
ERROR:django.request:Internal Server Error: /
Traceback (most recent call last):
  File "/usr/local/lib/python3.6/site-packages/django/contrib/sessions/backends/base.py", line 202, in _get_session
    return self._session_cache
AttributeError: 'SessionStore' object has no attribute '_session_cache'

During handling of the above exception, another exception occurred:

Traceback (most recent call last):
  File "/usr/local/lib/python3.6/site-packages/django/db/backends/utils.py", line 65, in execute
    return self.cursor.execute(sql, params)
psycopg2.ProgrammingError: permission denied for relation django_session


The above exception was the direct cause of the following exception:

Traceback (most recent call last):
  File "/usr/local/lib/python3.6/site-packages/django/core/handlers/exception.py", line 41, in inner
    response = get_response(request)
  File "/usr/local/lib/python3.6/site-packages/django/utils/deprecation.py", line 142, in __call__
    response = self.process_response(request, response)
  File "/usr/local/lib/python3.6/site-packages/django/contrib/sessions/middleware.py", line 47, in process_response
    if request.session.get_expire_at_browser_close():
  File "/usr/local/lib/python3.6/site-packages/django/contrib/sessions/backends/base.py", line 292, in get_expire_at_browser_close
    if self.get('_session_expiry') is None:
  File "/usr/local/lib/python3.6/site-packages/django/contrib/sessions/backends/base.py", line 68, in get
    return self._session.get(key, default)
  File "/usr/local/lib/python3.6/site-packages/django/contrib/sessions/backends/base.py", line 207, in _get_session
    self._session_cache = self.load()
  File "/usr/local/lib/python3.6/site-packages/django/contrib/sessions/backends/db.py", line 35, in load
    expire_date__gt=timezone.now()
  File "/usr/local/lib/python3.6/site-packages/django/db/models/manager.py", line 85, in manager_method
    return getattr(self.get_queryset(), name)(*args, **kwargs)
  File "/usr/local/lib/python3.6/site-packages/django/db/models/query.py", line 374, in get
    num = len(clone)
  File "/usr/local/lib/python3.6/site-packages/django/db/models/query.py", line 232, in __len__
    self._fetch_all()
  File "/usr/local/lib/python3.6/site-packages/django/db/models/query.py", line 1105, in _fetch_all
    self._result_cache = list(self._iterable_class(self))
  File "/usr/local/lib/python3.6/site-packages/django/db/models/query.py", line 53, in __iter__
    results = compiler.execute_sql(chunked_fetch=self.chunked_fetch)
  File "/usr/local/lib/python3.6/site-packages/django/db/models/sql/compiler.py", line 886, in execute_sql
    raise original_exception
  File "/usr/local/lib/python3.6/site-packages/django/db/models/sql/compiler.py", line 876, in execute_sql
    cursor.execute(sql, params)
  File "/usr/local/lib/python3.6/site-packages/django/db/backends/utils.py", line 80, in execute
    return super(CursorDebugWrapper, self).execute(sql, params)
  File "/usr/local/lib/python3.6/site-packages/django/db/backends/utils.py", line 65, in execute
    return self.cursor.execute(sql, params)
  File "/usr/local/lib/python3.6/site-packages/django/db/utils.py", line 94, in __exit__
    six.reraise(dj_exc_type, dj_exc_value, traceback)
  File "/usr/local/lib/python3.6/site-packages/django/utils/six.py", line 685, in reraise
    raise value.with_traceback(tb)
  File "/usr/local/lib/python3.6/site-packages/django/db/backends/utils.py", line 65, in execute
    return self.cursor.execute(sql, params)
django.db.utils.ProgrammingError: permission denied for relation django_session

ERROR:django.request:Internal Server Error: /favicon.ico
Traceback (most recent call last):
  File "/usr/local/lib/python3.6/site-packages/django/contrib/sessions/backends/base.py", line 202, in _get_session
    return self._session_cache
AttributeError: 'SessionStore' object has no attribute '_session_cache'

During handling of the above exception, another exception occurred:

Traceback (most recent call last):
  File "/usr/local/lib/python3.6/site-packages/django/db/backends/utils.py", line 65, in execute
    return self.cursor.execute(sql, params)
psycopg2.ProgrammingError: permission denied for relation django_session


The above exception was the direct cause of the following exception:

Traceback (most recent call last):
  File "/usr/local/lib/python3.6/site-packages/django/core/handlers/exception.py", line 41, in inner
    response = get_response(request)
  File "/usr/local/lib/python3.6/site-packages/django/utils/deprecation.py", line 142, in __call__
    response = self.process_response(request, response)
  File "/usr/local/lib/python3.6/site-packages/django/contrib/sessions/middleware.py", line 47, in process_response
    if request.session.get_expire_at_browser_close():
  File "/usr/local/lib/python3.6/site-packages/django/contrib/sessions/backends/base.py", line 292, in get_expire_at_browser_close
    if self.get('_session_expiry') is None:
  File "/usr/local/lib/python3.6/site-packages/django/contrib/sessions/backends/base.py", line 68, in get
    return self._session.get(key, default)
  File "/usr/local/lib/python3.6/site-packages/django/contrib/sessions/backends/base.py", line 207, in _get_session
    self._session_cache = self.load()
  File "/usr/local/lib/python3.6/site-packages/django/contrib/sessions/backends/db.py", line 35, in load
    expire_date__gt=timezone.now()
  File "/usr/local/lib/python3.6/site-packages/django/db/models/manager.py", line 85, in manager_method
    return getattr(self.get_queryset(), name)(*args, **kwargs)
  File "/usr/local/lib/python3.6/site-packages/django/db/models/query.py", line 374, in get
    num = len(clone)
  File "/usr/local/lib/python3.6/site-packages/django/db/models/query.py", line 232, in __len__
    self._fetch_all()
  File "/usr/local/lib/python3.6/site-packages/django/db/models/query.py", line 1105, in _fetch_all
    self._result_cache = list(self._iterable_class(self))
  File "/usr/local/lib/python3.6/site-packages/django/db/models/query.py", line 53, in __iter__
    results = compiler.execute_sql(chunked_fetch=self.chunked_fetch)
  File "/usr/local/lib/python3.6/site-packages/django/db/models/sql/compiler.py", line 886, in execute_sql
    raise original_exception
  File "/usr/local/lib/python3.6/site-packages/django/db/models/sql/compiler.py", line 876, in execute_sql
    cursor.execute(sql, params)
  File "/usr/local/lib/python3.6/site-packages/django/db/backends/utils.py", line 80, in execute
    return super(CursorDebugWrapper, self).execute(sql, params)
  File "/usr/local/lib/python3.6/site-packages/django/db/backends/utils.py", line 65, in execute
    return self.cursor.execute(sql, params)
  File "/usr/local/lib/python3.6/site-packages/django/db/utils.py", line 94, in __exit__
    six.reraise(dj_exc_type, dj_exc_value, traceback)
  File "/usr/local/lib/python3.6/site-packages/django/utils/six.py", line 685, in reraise
    raise value.with_traceback(tb)
  File "/usr/local/lib/python3.6/site-packages/django/db/backends/utils.py", line 65, in execute
    return self.cursor.execute(sql, params)
django.db.utils.ProgrammingError: permission denied for relation django_session

ERROR:django.request:Internal Server Error: /index
Traceback (most recent call last):
  File "/usr/local/lib/python3.6/site-packages/django/contrib/sessions/backends/base.py", line 202, in _get_session
    return self._session_cache
AttributeError: 'SessionStore' object has no attribute '_session_cache'

During handling of the above exception, another exception occurred:

Traceback (most recent call last):
  File "/usr/local/lib/python3.6/site-packages/django/db/backends/utils.py", line 65, in execute
    return self.cursor.execute(sql, params)
psycopg2.ProgrammingError: permission denied for relation django_session


The above exception was the direct cause of the following exception:

Traceback (most recent call last):
  File "/usr/local/lib/python3.6/site-packages/django/core/handlers/exception.py", line 41, in inner
    response = get_response(request)
  File "/usr/local/lib/python3.6/site-packages/django/utils/deprecation.py", line 142, in __call__
    response = self.process_response(request, response)
  File "/usr/local/lib/python3.6/site-packages/django/contrib/sessions/middleware.py", line 47, in process_response
    if request.session.get_expire_at_browser_close():
  File "/usr/local/lib/python3.6/site-packages/django/contrib/sessions/backends/base.py", line 292, in get_expire_at_browser_close
    if self.get('_session_expiry') is None:
  File "/usr/local/lib/python3.6/site-packages/django/contrib/sessions/backends/base.py", line 68, in get
    return self._session.get(key, default)
  File "/usr/local/lib/python3.6/site-packages/django/contrib/sessions/backends/base.py", line 207, in _get_session
    self._session_cache = self.load()
  File "/usr/local/lib/python3.6/site-packages/django/contrib/sessions/backends/db.py", line 35, in load
    expire_date__gt=timezone.now()
  File "/usr/local/lib/python3.6/site-packages/django/db/models/manager.py", line 85, in manager_method
    return getattr(self.get_queryset(), name)(*args, **kwargs)
  File "/usr/local/lib/python3.6/site-packages/django/db/models/query.py", line 374, in get
    num = len(clone)
  File "/usr/local/lib/python3.6/site-packages/django/db/models/query.py", line 232, in __len__
    self._fetch_all()
  File "/usr/local/lib/python3.6/site-packages/django/db/models/query.py", line 1105, in _fetch_all
    self._result_cache = list(self._iterable_class(self))
  File "/usr/local/lib/python3.6/site-packages/django/db/models/query.py", line 53, in __iter__
    results = compiler.execute_sql(chunked_fetch=self.chunked_fetch)
  File "/usr/local/lib/python3.6/site-packages/django/db/models/sql/compiler.py", line 886, in execute_sql
    raise original_exception
  File "/usr/local/lib/python3.6/site-packages/django/db/models/sql/compiler.py", line 876, in execute_sql
    cursor.execute(sql, params)
  File "/usr/local/lib/python3.6/site-packages/django/db/backends/utils.py", line 80, in execute
    return super(CursorDebugWrapper, self).execute(sql, params)
  File "/usr/local/lib/python3.6/site-packages/django/db/backends/utils.py", line 65, in execute
    return self.cursor.execute(sql, params)
  File "/usr/local/lib/python3.6/site-packages/django/db/utils.py", line 94, in __exit__
    six.reraise(dj_exc_type, dj_exc_value, traceback)
  File "/usr/local/lib/python3.6/site-packages/django/utils/six.py", line 685, in reraise
    raise value.with_traceback(tb)
  File "/usr/local/lib/python3.6/site-packages/django/db/backends/utils.py", line 65, in execute
    return self.cursor.execute(sql, params)
django.db.utils.ProgrammingError: permission denied for relation django_session

ERROR:django.request:Internal Server Error: /favicon.ico
Traceback (most recent call last):
  File "/usr/local/lib/python3.6/site-packages/django/contrib/sessions/backends/base.py", line 202, in _get_session
    return self._session_cache
AttributeError: 'SessionStore' object has no attribute '_session_cache'

During handling of the above exception, another exception occurred:

Traceback (most recent call last):
  File "/usr/local/lib/python3.6/site-packages/django/db/backends/utils.py", line 65, in execute
    return self.cursor.execute(sql, params)
psycopg2.ProgrammingError: permission denied for relation django_session


The above exception was the direct cause of the following exception:

Traceback (most recent call last):
  File "/usr/local/lib/python3.6/site-packages/django/core/handlers/exception.py", line 41, in inner
    response = get_response(request)
  File "/usr/local/lib/python3.6/site-packages/django/utils/deprecation.py", line 142, in __call__
    response = self.process_response(request, response)
  File "/usr/local/lib/python3.6/site-packages/django/contrib/sessions/middleware.py", line 47, in process_response
    if request.session.get_expire_at_browser_close():
  File "/usr/local/lib/python3.6/site-packages/django/contrib/sessions/backends/base.py", line 292, in get_expire_at_browser_close
    if self.get('_session_expiry') is None:
  File "/usr/local/lib/python3.6/site-packages/django/contrib/sessions/backends/base.py", line 68, in get
    return self._session.get(key, default)
  File "/usr/local/lib/python3.6/site-packages/django/contrib/sessions/backends/base.py", line 207, in _get_session
    self._session_cache = self.load()
  File "/usr/local/lib/python3.6/site-packages/django/contrib/sessions/backends/db.py", line 35, in load
    expire_date__gt=timezone.now()
  File "/usr/local/lib/python3.6/site-packages/django/db/models/manager.py", line 85, in manager_method
    return getattr(self.get_queryset(), name)(*args, **kwargs)
  File "/usr/local/lib/python3.6/site-packages/django/db/models/query.py", line 374, in get
    num = len(clone)
  File "/usr/local/lib/python3.6/site-packages/django/db/models/query.py", line 232, in __len__
    self._fetch_all()
  File "/usr/local/lib/python3.6/site-packages/django/db/models/query.py", line 1105, in _fetch_all
    self._result_cache = list(self._iterable_class(self))
  File "/usr/local/lib/python3.6/site-packages/django/db/models/query.py", line 53, in __iter__
    results = compiler.execute_sql(chunked_fetch=self.chunked_fetch)
  File "/usr/local/lib/python3.6/site-packages/django/db/models/sql/compiler.py", line 886, in execute_sql
    raise original_exception
  File "/usr/local/lib/python3.6/site-packages/django/db/models/sql/compiler.py", line 876, in execute_sql
    cursor.execute(sql, params)
  File "/usr/local/lib/python3.6/site-packages/django/db/backends/utils.py", line 80, in execute
    return super(CursorDebugWrapper, self).execute(sql, params)
  File "/usr/local/lib/python3.6/site-packages/django/db/backends/utils.py", line 65, in execute
    return self.cursor.execute(sql, params)
  File "/usr/local/lib/python3.6/site-packages/django/db/utils.py", line 94, in __exit__
    six.reraise(dj_exc_type, dj_exc_value, traceback)
  File "/usr/local/lib/python3.6/site-packages/django/utils/six.py", line 685, in reraise
    raise value.with_traceback(tb)
  File "/usr/local/lib/python3.6/site-packages/django/db/backends/utils.py", line 65, in execute
    return self.cursor.execute(sql, params)
django.db.utils.ProgrammingError: permission denied for relation django_session

ERROR:django.request:Internal Server Error: /index/
Traceback (most recent call last):
  File "/usr/local/lib/python3.6/site-packages/django/contrib/sessions/backends/base.py", line 202, in _get_session
    return self._session_cache
AttributeError: 'SessionStore' object has no attribute '_session_cache'

During handling of the above exception, another exception occurred:

Traceback (most recent call last):
  File "/usr/local/lib/python3.6/site-packages/django/db/backends/utils.py", line 65, in execute
    return self.cursor.execute(sql, params)
psycopg2.ProgrammingError: permission denied for relation django_session


The above exception was the direct cause of the following exception:

Traceback (most recent call last):
  File "/usr/local/lib/python3.6/site-packages/django/core/handlers/exception.py", line 41, in inner
    response = get_response(request)
  File "/usr/local/lib/python3.6/site-packages/django/utils/deprecation.py", line 142, in __call__
    response = self.process_response(request, response)
  File "/usr/local/lib/python3.6/site-packages/django/contrib/sessions/middleware.py", line 47, in process_response
    if request.session.get_expire_at_browser_close():
  File "/usr/local/lib/python3.6/site-packages/django/contrib/sessions/backends/base.py", line 292, in get_expire_at_browser_close
    if self.get('_session_expiry') is None:
  File "/usr/local/lib/python3.6/site-packages/django/contrib/sessions/backends/base.py", line 68, in get
    return self._session.get(key, default)
  File "/usr/local/lib/python3.6/site-packages/django/contrib/sessions/backends/base.py", line 207, in _get_session
    self._session_cache = self.load()
  File "/usr/local/lib/python3.6/site-packages/django/contrib/sessions/backends/db.py", line 35, in load
    expire_date__gt=timezone.now()
  File "/usr/local/lib/python3.6/site-packages/django/db/models/manager.py", line 85, in manager_method
    return getattr(self.get_queryset(), name)(*args, **kwargs)
  File "/usr/local/lib/python3.6/site-packages/django/db/models/query.py", line 374, in get
    num = len(clone)
  File "/usr/local/lib/python3.6/site-packages/django/db/models/query.py", line 232, in __len__
    self._fetch_all()
  File "/usr/local/lib/python3.6/site-packages/django/db/models/query.py", line 1105, in _fetch_all
    self._result_cache = list(self._iterable_class(self))
  File "/usr/local/lib/python3.6/site-packages/django/db/models/query.py", line 53, in __iter__
    results = compiler.execute_sql(chunked_fetch=self.chunked_fetch)
  File "/usr/local/lib/python3.6/site-packages/django/db/models/sql/compiler.py", line 886, in execute_sql
    raise original_exception
  File "/usr/local/lib/python3.6/site-packages/django/db/models/sql/compiler.py", line 876, in execute_sql
    cursor.execute(sql, params)
  File "/usr/local/lib/python3.6/site-packages/django/db/backends/utils.py", line 80, in execute
    return super(CursorDebugWrapper, self).execute(sql, params)
  File "/usr/local/lib/python3.6/site-packages/django/db/backends/utils.py", line 65, in execute
    return self.cursor.execute(sql, params)
  File "/usr/local/lib/python3.6/site-packages/django/db/utils.py", line 94, in __exit__
    six.reraise(dj_exc_type, dj_exc_value, traceback)
  File "/usr/local/lib/python3.6/site-packages/django/utils/six.py", line 685, in reraise
    raise value.with_traceback(tb)
  File "/usr/local/lib/python3.6/site-packages/django/db/backends/utils.py", line 65, in execute
    return self.cursor.execute(sql, params)
django.db.utils.ProgrammingError: permission denied for relation django_session

ERROR:django.request:Internal Server Error: /favicon.ico
Traceback (most recent call last):
  File "/usr/local/lib/python3.6/site-packages/django/contrib/sessions/backends/base.py", line 202, in _get_session
    return self._session_cache
AttributeError: 'SessionStore' object has no attribute '_session_cache'

During handling of the above exception, another exception occurred:

Traceback (most recent call last):
  File "/usr/local/lib/python3.6/site-packages/django/db/backends/utils.py", line 65, in execute
    return self.cursor.execute(sql, params)
psycopg2.ProgrammingError: permission denied for relation django_session


The above exception was the direct cause of the following exception:

Traceback (most recent call last):
  File "/usr/local/lib/python3.6/site-packages/django/core/handlers/exception.py", line 41, in inner
    response = get_response(request)
  File "/usr/local/lib/python3.6/site-packages/django/utils/deprecation.py", line 142, in __call__
    response = self.process_response(request, response)
  File "/usr/local/lib/python3.6/site-packages/django/contrib/sessions/middleware.py", line 47, in process_response
    if request.session.get_expire_at_browser_close():
  File "/usr/local/lib/python3.6/site-packages/django/contrib/sessions/backends/base.py", line 292, in get_expire_at_browser_close
    if self.get('_session_expiry') is None:
  File "/usr/local/lib/python3.6/site-packages/django/contrib/sessions/backends/base.py", line 68, in get
    return self._session.get(key, default)
  File "/usr/local/lib/python3.6/site-packages/django/contrib/sessions/backends/base.py", line 207, in _get_session
    self._session_cache = self.load()
  File "/usr/local/lib/python3.6/site-packages/django/contrib/sessions/backends/db.py", line 35, in load
    expire_date__gt=timezone.now()
  File "/usr/local/lib/python3.6/site-packages/django/db/models/manager.py", line 85, in manager_method
    return getattr(self.get_queryset(), name)(*args, **kwargs)
  File "/usr/local/lib/python3.6/site-packages/django/db/models/query.py", line 374, in get
    num = len(clone)
  File "/usr/local/lib/python3.6/site-packages/django/db/models/query.py", line 232, in __len__
    self._fetch_all()
  File "/usr/local/lib/python3.6/site-packages/django/db/models/query.py", line 1105, in _fetch_all
    self._result_cache = list(self._iterable_class(self))
  File "/usr/local/lib/python3.6/site-packages/django/db/models/query.py", line 53, in __iter__
    results = compiler.execute_sql(chunked_fetch=self.chunked_fetch)
  File "/usr/local/lib/python3.6/site-packages/django/db/models/sql/compiler.py", line 886, in execute_sql
    raise original_exception
  File "/usr/local/lib/python3.6/site-packages/django/db/models/sql/compiler.py", line 876, in execute_sql
    cursor.execute(sql, params)
  File "/usr/local/lib/python3.6/site-packages/django/db/backends/utils.py", line 80, in execute
    return super(CursorDebugWrapper, self).execute(sql, params)
  File "/usr/local/lib/python3.6/site-packages/django/db/backends/utils.py", line 65, in execute
    return self.cursor.execute(sql, params)
  File "/usr/local/lib/python3.6/site-packages/django/db/utils.py", line 94, in __exit__
    six.reraise(dj_exc_type, dj_exc_value, traceback)
  File "/usr/local/lib/python3.6/site-packages/django/utils/six.py", line 685, in reraise
    raise value.with_traceback(tb)
  File "/usr/local/lib/python3.6/site-packages/django/db/backends/utils.py", line 65, in execute
    return self.cursor.execute(sql, params)
django.db.utils.ProgrammingError: permission denied for relation django_session

ERROR:django.request:Internal Server Error: /admin/
Traceback (most recent call last):
  File "/usr/local/lib/python3.6/site-packages/django/contrib/sessions/backends/base.py", line 202, in _get_session
    return self._session_cache
AttributeError: 'SessionStore' object has no attribute '_session_cache'

During handling of the above exception, another exception occurred:

Traceback (most recent call last):
  File "/usr/local/lib/python3.6/site-packages/django/db/backends/utils.py", line 65, in execute
    return self.cursor.execute(sql, params)
psycopg2.ProgrammingError: permission denied for relation django_session


The above exception was the direct cause of the following exception:

Traceback (most recent call last):
  File "/usr/local/lib/python3.6/site-packages/django/core/handlers/exception.py", line 41, in inner
    response = get_response(request)
  File "/usr/local/lib/python3.6/site-packages/django/core/handlers/base.py", line 187, in _get_response
    response = self.process_exception_by_middleware(e, request)
  File "/usr/local/lib/python3.6/site-packages/django/core/handlers/base.py", line 185, in _get_response
    response = wrapped_callback(request, *callback_args, **callback_kwargs)
  File "/usr/local/lib/python3.6/site-packages/django/contrib/admin/sites.py", line 242, in wrapper
    return self.admin_view(view, cacheable)(*args, **kwargs)
  File "/usr/local/lib/python3.6/site-packages/django/utils/decorators.py", line 149, in _wrapped_view
    response = view_func(request, *args, **kwargs)
  File "/usr/local/lib/python3.6/site-packages/django/views/decorators/cache.py", line 57, in _wrapped_view_func
    response = view_func(request, *args, **kwargs)
  File "/usr/local/lib/python3.6/site-packages/django/contrib/admin/sites.py", line 213, in inner
    if not self.has_permission(request):
  File "/usr/local/lib/python3.6/site-packages/django/contrib/admin/sites.py", line 187, in has_permission
    return request.user.is_active and request.user.is_staff
  File "/usr/local/lib/python3.6/site-packages/django/utils/functional.py", line 238, in inner
    self._setup()
  File "/usr/local/lib/python3.6/site-packages/django/utils/functional.py", line 385, in _setup
    self._wrapped = self._setupfunc()
  File "/usr/local/lib/python3.6/site-packages/django/contrib/auth/middleware.py", line 24, in <lambda>
    request.user = SimpleLazyObject(lambda: get_user(request))
  File "/usr/local/lib/python3.6/site-packages/django/contrib/auth/middleware.py", line 12, in get_user
    request._cached_user = auth.get_user(request)
  File "/usr/local/lib/python3.6/site-packages/django/contrib/auth/__init__.py", line 210, in get_user
    user_id = _get_user_session_key(request)
  File "/usr/local/lib/python3.6/site-packages/django/contrib/auth/__init__.py", line 61, in _get_user_session_key
    return get_user_model()._meta.pk.to_python(request.session[SESSION_KEY])
  File "/usr/local/lib/python3.6/site-packages/django/contrib/sessions/backends/base.py", line 57, in __getitem__
    return self._session[key]
  File "/usr/local/lib/python3.6/site-packages/django/contrib/sessions/backends/base.py", line 207, in _get_session
    self._session_cache = self.load()
  File "/usr/local/lib/python3.6/site-packages/django/contrib/sessions/backends/db.py", line 35, in load
    expire_date__gt=timezone.now()
  File "/usr/local/lib/python3.6/site-packages/django/db/models/manager.py", line 85, in manager_method
    return getattr(self.get_queryset(), name)(*args, **kwargs)
  File "/usr/local/lib/python3.6/site-packages/django/db/models/query.py", line 374, in get
    num = len(clone)
  File "/usr/local/lib/python3.6/site-packages/django/db/models/query.py", line 232, in __len__
    self._fetch_all()
  File "/usr/local/lib/python3.6/site-packages/django/db/models/query.py", line 1105, in _fetch_all
    self._result_cache = list(self._iterable_class(self))
  File "/usr/local/lib/python3.6/site-packages/django/db/models/query.py", line 53, in __iter__
    results = compiler.execute_sql(chunked_fetch=self.chunked_fetch)
  File "/usr/local/lib/python3.6/site-packages/django/db/models/sql/compiler.py", line 886, in execute_sql
    raise original_exception
  File "/usr/local/lib/python3.6/site-packages/django/db/models/sql/compiler.py", line 876, in execute_sql
    cursor.execute(sql, params)
  File "/usr/local/lib/python3.6/site-packages/django/db/backends/utils.py", line 80, in execute
    return super(CursorDebugWrapper, self).execute(sql, params)
  File "/usr/local/lib/python3.6/site-packages/django/db/backends/utils.py", line 65, in execute
    return self.cursor.execute(sql, params)
  File "/usr/local/lib/python3.6/site-packages/django/db/utils.py", line 94, in __exit__
    six.reraise(dj_exc_type, dj_exc_value, traceback)
  File "/usr/local/lib/python3.6/site-packages/django/utils/six.py", line 685, in reraise
    raise value.with_traceback(tb)
  File "/usr/local/lib/python3.6/site-packages/django/db/backends/utils.py", line 65, in execute
    return self.cursor.execute(sql, params)
django.db.utils.ProgrammingError: permission denied for relation django_session

ERROR:django.request:Internal Server Error: /admin/
Traceback (most recent call last):
  File "/usr/local/lib/python3.6/site-packages/django/contrib/sessions/backends/base.py", line 202, in _get_session
    return self._session_cache
AttributeError: 'SessionStore' object has no attribute '_session_cache'

During handling of the above exception, another exception occurred:

Traceback (most recent call last):
  File "/usr/local/lib/python3.6/site-packages/django/db/backends/utils.py", line 65, in execute
    return self.cursor.execute(sql, params)
psycopg2.ProgrammingError: permission denied for relation django_session


The above exception was the direct cause of the following exception:

Traceback (most recent call last):
  File "/usr/local/lib/python3.6/site-packages/django/core/handlers/exception.py", line 41, in inner
    response = get_response(request)
  File "/usr/local/lib/python3.6/site-packages/django/utils/deprecation.py", line 142, in __call__
    response = self.process_response(request, response)
  File "/usr/local/lib/python3.6/site-packages/django/contrib/sessions/middleware.py", line 47, in process_response
    if request.session.get_expire_at_browser_close():
  File "/usr/local/lib/python3.6/site-packages/django/contrib/sessions/backends/base.py", line 292, in get_expire_at_browser_close
    if self.get('_session_expiry') is None:
  File "/usr/local/lib/python3.6/site-packages/django/contrib/sessions/backends/base.py", line 68, in get
    return self._session.get(key, default)
  File "/usr/local/lib/python3.6/site-packages/django/contrib/sessions/backends/base.py", line 207, in _get_session
    self._session_cache = self.load()
  File "/usr/local/lib/python3.6/site-packages/django/contrib/sessions/backends/db.py", line 35, in load
    expire_date__gt=timezone.now()
  File "/usr/local/lib/python3.6/site-packages/django/db/models/manager.py", line 85, in manager_method
    return getattr(self.get_queryset(), name)(*args, **kwargs)
  File "/usr/local/lib/python3.6/site-packages/django/db/models/query.py", line 374, in get
    num = len(clone)
  File "/usr/local/lib/python3.6/site-packages/django/db/models/query.py", line 232, in __len__
    self._fetch_all()
  File "/usr/local/lib/python3.6/site-packages/django/db/models/query.py", line 1105, in _fetch_all
    self._result_cache = list(self._iterable_class(self))
  File "/usr/local/lib/python3.6/site-packages/django/db/models/query.py", line 53, in __iter__
    results = compiler.execute_sql(chunked_fetch=self.chunked_fetch)
  File "/usr/local/lib/python3.6/site-packages/django/db/models/sql/compiler.py", line 886, in execute_sql
    raise original_exception
  File "/usr/local/lib/python3.6/site-packages/django/db/models/sql/compiler.py", line 876, in execute_sql
    cursor.execute(sql, params)
  File "/usr/local/lib/python3.6/site-packages/django/db/backends/utils.py", line 80, in execute
    return super(CursorDebugWrapper, self).execute(sql, params)
  File "/usr/local/lib/python3.6/site-packages/django/db/backends/utils.py", line 65, in execute
    return self.cursor.execute(sql, params)
  File "/usr/local/lib/python3.6/site-packages/django/db/utils.py", line 94, in __exit__
    six.reraise(dj_exc_type, dj_exc_value, traceback)
  File "/usr/local/lib/python3.6/site-packages/django/utils/six.py", line 685, in reraise
    raise value.with_traceback(tb)
  File "/usr/local/lib/python3.6/site-packages/django/db/backends/utils.py", line 65, in execute
    return self.cursor.execute(sql, params)
django.db.utils.ProgrammingError: permission denied for relation django_session

ERROR:django.request:Internal Server Error: /favicon.ico
Traceback (most recent call last):
  File "/usr/local/lib/python3.6/site-packages/django/contrib/sessions/backends/base.py", line 202, in _get_session
    return self._session_cache
AttributeError: 'SessionStore' object has no attribute '_session_cache'

During handling of the above exception, another exception occurred:

Traceback (most recent call last):
  File "/usr/local/lib/python3.6/site-packages/django/db/backends/utils.py", line 65, in execute
    return self.cursor.execute(sql, params)
psycopg2.ProgrammingError: permission denied for relation django_session


The above exception was the direct cause of the following exception:

Traceback (most recent call last):
  File "/usr/local/lib/python3.6/site-packages/django/core/handlers/exception.py", line 41, in inner
    response = get_response(request)
  File "/usr/local/lib/python3.6/site-packages/django/utils/deprecation.py", line 142, in __call__
    response = self.process_response(request, response)
  File "/usr/local/lib/python3.6/site-packages/django/contrib/sessions/middleware.py", line 47, in process_response
    if request.session.get_expire_at_browser_close():
  File "/usr/local/lib/python3.6/site-packages/django/contrib/sessions/backends/base.py", line 292, in get_expire_at_browser_close
    if self.get('_session_expiry') is None:
  File "/usr/local/lib/python3.6/site-packages/django/contrib/sessions/backends/base.py", line 68, in get
    return self._session.get(key, default)
  File "/usr/local/lib/python3.6/site-packages/django/contrib/sessions/backends/base.py", line 207, in _get_session
    self._session_cache = self.load()
  File "/usr/local/lib/python3.6/site-packages/django/contrib/sessions/backends/db.py", line 35, in load
    expire_date__gt=timezone.now()
  File "/usr/local/lib/python3.6/site-packages/django/db/models/manager.py", line 85, in manager_method
    return getattr(self.get_queryset(), name)(*args, **kwargs)
  File "/usr/local/lib/python3.6/site-packages/django/db/models/query.py", line 374, in get
    num = len(clone)
  File "/usr/local/lib/python3.6/site-packages/django/db/models/query.py", line 232, in __len__
    self._fetch_all()
  File "/usr/local/lib/python3.6/site-packages/django/db/models/query.py", line 1105, in _fetch_all
    self._result_cache = list(self._iterable_class(self))
  File "/usr/local/lib/python3.6/site-packages/django/db/models/query.py", line 53, in __iter__
    results = compiler.execute_sql(chunked_fetch=self.chunked_fetch)
  File "/usr/local/lib/python3.6/site-packages/django/db/models/sql/compiler.py", line 886, in execute_sql
    raise original_exception
  File "/usr/local/lib/python3.6/site-packages/django/db/models/sql/compiler.py", line 876, in execute_sql
    cursor.execute(sql, params)
  File "/usr/local/lib/python3.6/site-packages/django/db/backends/utils.py", line 80, in execute
    return super(CursorDebugWrapper, self).execute(sql, params)
  File "/usr/local/lib/python3.6/site-packages/django/db/backends/utils.py", line 65, in execute
    return self.cursor.execute(sql, params)
  File "/usr/local/lib/python3.6/site-packages/django/db/utils.py", line 94, in __exit__
    six.reraise(dj_exc_type, dj_exc_value, traceback)
  File "/usr/local/lib/python3.6/site-packages/django/utils/six.py", line 685, in reraise
    raise value.with_traceback(tb)
  File "/usr/local/lib/python3.6/site-packages/django/db/backends/utils.py", line 65, in execute
    return self.cursor.execute(sql, params)
django.db.utils.ProgrammingError: permission denied for relation django_session

ERROR:django.request:Internal Server Error: /admin
Traceback (most recent call last):
  File "/usr/local/lib/python3.6/site-packages/django/contrib/sessions/backends/base.py", line 202, in _get_session
    return self._session_cache
AttributeError: 'SessionStore' object has no attribute '_session_cache'

During handling of the above exception, another exception occurred:

Traceback (most recent call last):
  File "/usr/local/lib/python3.6/site-packages/django/db/backends/utils.py", line 65, in execute
    return self.cursor.execute(sql, params)
psycopg2.ProgrammingError: permission denied for relation django_session


The above exception was the direct cause of the following exception:

Traceback (most recent call last):
  File "/usr/local/lib/python3.6/site-packages/django/core/handlers/exception.py", line 41, in inner
    response = get_response(request)
  File "/usr/local/lib/python3.6/site-packages/django/utils/deprecation.py", line 142, in __call__
    response = self.process_response(request, response)
  File "/usr/local/lib/python3.6/site-packages/django/contrib/sessions/middleware.py", line 47, in process_response
    if request.session.get_expire_at_browser_close():
  File "/usr/local/lib/python3.6/site-packages/django/contrib/sessions/backends/base.py", line 292, in get_expire_at_browser_close
    if self.get('_session_expiry') is None:
  File "/usr/local/lib/python3.6/site-packages/django/contrib/sessions/backends/base.py", line 68, in get
    return self._session.get(key, default)
  File "/usr/local/lib/python3.6/site-packages/django/contrib/sessions/backends/base.py", line 207, in _get_session
    self._session_cache = self.load()
  File "/usr/local/lib/python3.6/site-packages/django/contrib/sessions/backends/db.py", line 35, in load
    expire_date__gt=timezone.now()
  File "/usr/local/lib/python3.6/site-packages/django/db/models/manager.py", line 85, in manager_method
    return getattr(self.get_queryset(), name)(*args, **kwargs)
  File "/usr/local/lib/python3.6/site-packages/django/db/models/query.py", line 374, in get
    num = len(clone)
  File "/usr/local/lib/python3.6/site-packages/django/db/models/query.py", line 232, in __len__
    self._fetch_all()
  File "/usr/local/lib/python3.6/site-packages/django/db/models/query.py", line 1105, in _fetch_all
    self._result_cache = list(self._iterable_class(self))
  File "/usr/local/lib/python3.6/site-packages/django/db/models/query.py", line 53, in __iter__
    results = compiler.execute_sql(chunked_fetch=self.chunked_fetch)
  File "/usr/local/lib/python3.6/site-packages/django/db/models/sql/compiler.py", line 886, in execute_sql
    raise original_exception
  File "/usr/local/lib/python3.6/site-packages/django/db/models/sql/compiler.py", line 876, in execute_sql
    cursor.execute(sql, params)
  File "/usr/local/lib/python3.6/site-packages/django/db/backends/utils.py", line 80, in execute
    return super(CursorDebugWrapper, self).execute(sql, params)
  File "/usr/local/lib/python3.6/site-packages/django/db/backends/utils.py", line 65, in execute
    return self.cursor.execute(sql, params)
  File "/usr/local/lib/python3.6/site-packages/django/db/utils.py", line 94, in __exit__
    six.reraise(dj_exc_type, dj_exc_value, traceback)
  File "/usr/local/lib/python3.6/site-packages/django/utils/six.py", line 685, in reraise
    raise value.with_traceback(tb)
  File "/usr/local/lib/python3.6/site-packages/django/db/backends/utils.py", line 65, in execute
    return self.cursor.execute(sql, params)
django.db.utils.ProgrammingError: permission denied for relation django_session

ERROR:django.request:Internal Server Error: /favicon.ico
Traceback (most recent call last):
  File "/usr/local/lib/python3.6/site-packages/django/contrib/sessions/backends/base.py", line 202, in _get_session
    return self._session_cache
AttributeError: 'SessionStore' object has no attribute '_session_cache'

During handling of the above exception, another exception occurred:

Traceback (most recent call last):
  File "/usr/local/lib/python3.6/site-packages/django/db/backends/utils.py", line 65, in execute
    return self.cursor.execute(sql, params)
psycopg2.ProgrammingError: permission denied for relation django_session


The above exception was the direct cause of the following exception:

Traceback (most recent call last):
  File "/usr/local/lib/python3.6/site-packages/django/core/handlers/exception.py", line 41, in inner
    response = get_response(request)
  File "/usr/local/lib/python3.6/site-packages/django/utils/deprecation.py", line 142, in __call__
    response = self.process_response(request, response)
  File "/usr/local/lib/python3.6/site-packages/django/contrib/sessions/middleware.py", line 47, in process_response
    if request.session.get_expire_at_browser_close():
  File "/usr/local/lib/python3.6/site-packages/django/contrib/sessions/backends/base.py", line 292, in get_expire_at_browser_close
    if self.get('_session_expiry') is None:
  File "/usr/local/lib/python3.6/site-packages/django/contrib/sessions/backends/base.py", line 68, in get
    return self._session.get(key, default)
  File "/usr/local/lib/python3.6/site-packages/django/contrib/sessions/backends/base.py", line 207, in _get_session
    self._session_cache = self.load()
  File "/usr/local/lib/python3.6/site-packages/django/contrib/sessions/backends/db.py", line 35, in load
    expire_date__gt=timezone.now()
  File "/usr/local/lib/python3.6/site-packages/django/db/models/manager.py", line 85, in manager_method
    return getattr(self.get_queryset(), name)(*args, **kwargs)
  File "/usr/local/lib/python3.6/site-packages/django/db/models/query.py", line 374, in get
    num = len(clone)
  File "/usr/local/lib/python3.6/site-packages/django/db/models/query.py", line 232, in __len__
    self._fetch_all()
  File "/usr/local/lib/python3.6/site-packages/django/db/models/query.py", line 1105, in _fetch_all
    self._result_cache = list(self._iterable_class(self))
  File "/usr/local/lib/python3.6/site-packages/django/db/models/query.py", line 53, in __iter__
    results = compiler.execute_sql(chunked_fetch=self.chunked_fetch)
  File "/usr/local/lib/python3.6/site-packages/django/db/models/sql/compiler.py", line 886, in execute_sql
    raise original_exception
  File "/usr/local/lib/python3.6/site-packages/django/db/models/sql/compiler.py", line 876, in execute_sql
    cursor.execute(sql, params)
  File "/usr/local/lib/python3.6/site-packages/django/db/backends/utils.py", line 80, in execute
    return super(CursorDebugWrapper, self).execute(sql, params)
  File "/usr/local/lib/python3.6/site-packages/django/db/backends/utils.py", line 65, in execute
    return self.cursor.execute(sql, params)
  File "/usr/local/lib/python3.6/site-packages/django/db/utils.py", line 94, in __exit__
    six.reraise(dj_exc_type, dj_exc_value, traceback)
  File "/usr/local/lib/python3.6/site-packages/django/utils/six.py", line 685, in reraise
    raise value.with_traceback(tb)
  File "/usr/local/lib/python3.6/site-packages/django/db/backends/utils.py", line 65, in execute
    return self.cursor.execute(sql, params)
django.db.utils.ProgrammingError: permission denied for relation django_session

WARNING:django.request:Not Found: /admin
WARNING:django.request:Not Found: /favicon.ico
WARNING:django.request:Not Found: /
WARNING:django.request:Not Found: /admin
WARNING:django.request:Not Found: /index
